{
 "cells": [
  {
   "cell_type": "code",
   "execution_count": 1,
   "id": "aee44d9f",
   "metadata": {},
   "outputs": [
    {
     "name": "stdout",
     "output_type": "stream",
     "text": [
      "Collecting pgmpy\n",
      "  Using cached pgmpy-0.1.19-py3-none-any.whl (1.9 MB)\n",
      "Requirement already satisfied: statsmodels in c:\\users\\sai gangadhar\\anaconda3\\lib\\site-packages (from pgmpy) (0.12.2)\n",
      "Requirement already satisfied: pandas in c:\\users\\sai gangadhar\\anaconda3\\lib\\site-packages (from pgmpy) (1.3.0)\n",
      "Requirement already satisfied: scikit-learn in c:\\users\\sai gangadhar\\anaconda3\\lib\\site-packages (from pgmpy) (0.24.2)\n",
      "Requirement already satisfied: pyparsing in c:\\users\\sai gangadhar\\anaconda3\\lib\\site-packages (from pgmpy) (3.0.4)\n",
      "Requirement already satisfied: networkx in c:\\users\\sai gangadhar\\anaconda3\\lib\\site-packages (from pgmpy) (2.6.3)\n",
      "Requirement already satisfied: tqdm in c:\\users\\sai gangadhar\\anaconda3\\lib\\site-packages (from pgmpy) (4.62.3)\n",
      "Collecting torch\n",
      "  Downloading torch-1.12.1-cp39-cp39-win_amd64.whl (161.8 MB)\n",
      "Note: you may need to restart the kernel to use updated packages.\n"
     ]
    },
    {
     "name": "stderr",
     "output_type": "stream",
     "text": [
      "WARNING: Retrying (Retry(total=4, connect=None, read=None, redirect=None, status=None)) after connection broken by 'ReadTimeoutError(\"HTTPSConnectionPool(host='pypi.org', port=443): Read timed out. (read timeout=15)\")': /simple/pgmpy/\n",
      "WARNING: Retrying (Retry(total=3, connect=None, read=None, redirect=None, status=None)) after connection broken by 'ReadTimeoutError(\"HTTPSConnectionPool(host='pypi.org', port=443): Read timed out. (read timeout=15)\")': /simple/pgmpy/\n",
      "ERROR: Exception:\n",
      "Traceback (most recent call last):\n",
      "  File \"C:\\Users\\SAI GANGADHAR\\anaconda3\\lib\\site-packages\\pip\\_vendor\\urllib3\\response.py\", line 438, in _error_catcher\n",
      "    yield\n",
      "  File \"C:\\Users\\SAI GANGADHAR\\anaconda3\\lib\\site-packages\\pip\\_vendor\\urllib3\\response.py\", line 519, in read\n",
      "    data = self._fp.read(amt) if not fp_closed else b\"\"\n",
      "  File \"C:\\Users\\SAI GANGADHAR\\anaconda3\\lib\\site-packages\\pip\\_vendor\\cachecontrol\\filewrapper.py\", line 62, in read\n",
      "    data = self.__fp.read(amt)\n",
      "  File \"C:\\Users\\SAI GANGADHAR\\anaconda3\\lib\\http\\client.py\", line 462, in read\n",
      "    n = self.readinto(b)\n",
      "  File \"C:\\Users\\SAI GANGADHAR\\anaconda3\\lib\\http\\client.py\", line 506, in readinto\n",
      "    n = self.fp.readinto(b)\n",
      "  File \"C:\\Users\\SAI GANGADHAR\\anaconda3\\lib\\socket.py\", line 704, in readinto\n",
      "    return self._sock.recv_into(b)\n",
      "  File \"C:\\Users\\SAI GANGADHAR\\anaconda3\\lib\\ssl.py\", line 1241, in recv_into\n",
      "    return self.read(nbytes, buffer)\n",
      "  File \"C:\\Users\\SAI GANGADHAR\\anaconda3\\lib\\ssl.py\", line 1099, in read\n",
      "    return self._sslobj.read(len, buffer)\n",
      "socket.timeout: The read operation timed out\n",
      "\n",
      "During handling of the above exception, another exception occurred:\n",
      "\n",
      "Traceback (most recent call last):\n",
      "  File \"C:\\Users\\SAI GANGADHAR\\anaconda3\\lib\\site-packages\\pip\\_internal\\cli\\base_command.py\", line 173, in _main\n",
      "    status = self.run(options, args)\n",
      "  File \"C:\\Users\\SAI GANGADHAR\\anaconda3\\lib\\site-packages\\pip\\_internal\\cli\\req_command.py\", line 203, in wrapper\n",
      "    return func(self, options, args)\n",
      "  File \"C:\\Users\\SAI GANGADHAR\\anaconda3\\lib\\site-packages\\pip\\_internal\\commands\\install.py\", line 315, in run\n",
      "    requirement_set = resolver.resolve(\n",
      "  File \"C:\\Users\\SAI GANGADHAR\\anaconda3\\lib\\site-packages\\pip\\_internal\\resolution\\resolvelib\\resolver.py\", line 94, in resolve\n",
      "    result = self._result = resolver.resolve(\n",
      "  File \"C:\\Users\\SAI GANGADHAR\\anaconda3\\lib\\site-packages\\pip\\_vendor\\resolvelib\\resolvers.py\", line 472, in resolve\n",
      "    state = resolution.resolve(requirements, max_rounds=max_rounds)\n",
      "  File \"C:\\Users\\SAI GANGADHAR\\anaconda3\\lib\\site-packages\\pip\\_vendor\\resolvelib\\resolvers.py\", line 366, in resolve\n",
      "    failure_causes = self._attempt_to_pin_criterion(name)\n",
      "  File \"C:\\Users\\SAI GANGADHAR\\anaconda3\\lib\\site-packages\\pip\\_vendor\\resolvelib\\resolvers.py\", line 212, in _attempt_to_pin_criterion\n",
      "    criteria = self._get_updated_criteria(candidate)\n",
      "  File \"C:\\Users\\SAI GANGADHAR\\anaconda3\\lib\\site-packages\\pip\\_vendor\\resolvelib\\resolvers.py\", line 203, in _get_updated_criteria\n",
      "    self._add_to_criteria(criteria, requirement, parent=candidate)\n",
      "  File \"C:\\Users\\SAI GANGADHAR\\anaconda3\\lib\\site-packages\\pip\\_vendor\\resolvelib\\resolvers.py\", line 172, in _add_to_criteria\n",
      "    if not criterion.candidates:\n",
      "  File \"C:\\Users\\SAI GANGADHAR\\anaconda3\\lib\\site-packages\\pip\\_vendor\\resolvelib\\structs.py\", line 151, in __bool__\n",
      "    return bool(self._sequence)\n",
      "  File \"C:\\Users\\SAI GANGADHAR\\anaconda3\\lib\\site-packages\\pip\\_internal\\resolution\\resolvelib\\found_candidates.py\", line 140, in __bool__\n",
      "    return any(self)\n",
      "  File \"C:\\Users\\SAI GANGADHAR\\anaconda3\\lib\\site-packages\\pip\\_internal\\resolution\\resolvelib\\found_candidates.py\", line 128, in <genexpr>\n",
      "    return (c for c in iterator if id(c) not in self._incompatible_ids)\n",
      "  File \"C:\\Users\\SAI GANGADHAR\\anaconda3\\lib\\site-packages\\pip\\_internal\\resolution\\resolvelib\\found_candidates.py\", line 32, in _iter_built\n",
      "    candidate = func()\n",
      "  File \"C:\\Users\\SAI GANGADHAR\\anaconda3\\lib\\site-packages\\pip\\_internal\\resolution\\resolvelib\\factory.py\", line 204, in _make_candidate_from_link\n",
      "    self._link_candidate_cache[link] = LinkCandidate(\n",
      "  File \"C:\\Users\\SAI GANGADHAR\\anaconda3\\lib\\site-packages\\pip\\_internal\\resolution\\resolvelib\\candidates.py\", line 295, in __init__\n",
      "    super().__init__(\n",
      "  File \"C:\\Users\\SAI GANGADHAR\\anaconda3\\lib\\site-packages\\pip\\_internal\\resolution\\resolvelib\\candidates.py\", line 156, in __init__\n",
      "    self.dist = self._prepare()\n",
      "  File \"C:\\Users\\SAI GANGADHAR\\anaconda3\\lib\\site-packages\\pip\\_internal\\resolution\\resolvelib\\candidates.py\", line 227, in _prepare\n",
      "    dist = self._prepare_distribution()\n",
      "  File \"C:\\Users\\SAI GANGADHAR\\anaconda3\\lib\\site-packages\\pip\\_internal\\resolution\\resolvelib\\candidates.py\", line 305, in _prepare_distribution\n",
      "    return self._factory.preparer.prepare_linked_requirement(\n",
      "  File \"C:\\Users\\SAI GANGADHAR\\anaconda3\\lib\\site-packages\\pip\\_internal\\operations\\prepare.py\", line 508, in prepare_linked_requirement\n",
      "    return self._prepare_linked_requirement(req, parallel_builds)\n",
      "  File \"C:\\Users\\SAI GANGADHAR\\anaconda3\\lib\\site-packages\\pip\\_internal\\operations\\prepare.py\", line 550, in _prepare_linked_requirement\n",
      "    local_file = unpack_url(\n",
      "  File \"C:\\Users\\SAI GANGADHAR\\anaconda3\\lib\\site-packages\\pip\\_internal\\operations\\prepare.py\", line 239, in unpack_url\n",
      "    file = get_http_url(\n",
      "  File \"C:\\Users\\SAI GANGADHAR\\anaconda3\\lib\\site-packages\\pip\\_internal\\operations\\prepare.py\", line 102, in get_http_url\n",
      "    from_path, content_type = download(link, temp_dir.path)\n",
      "  File \"C:\\Users\\SAI GANGADHAR\\anaconda3\\lib\\site-packages\\pip\\_internal\\network\\download.py\", line 145, in __call__\n",
      "    for chunk in chunks:\n",
      "  File \"C:\\Users\\SAI GANGADHAR\\anaconda3\\lib\\site-packages\\pip\\_internal\\cli\\progress_bars.py\", line 144, in iter\n",
      "    for x in it:\n",
      "  File \"C:\\Users\\SAI GANGADHAR\\anaconda3\\lib\\site-packages\\pip\\_internal\\network\\utils.py\", line 63, in response_chunks\n",
      "    for chunk in response.raw.stream(\n",
      "  File \"C:\\Users\\SAI GANGADHAR\\anaconda3\\lib\\site-packages\\pip\\_vendor\\urllib3\\response.py\", line 576, in stream\n",
      "    data = self.read(amt=amt, decode_content=decode_content)\n",
      "  File \"C:\\Users\\SAI GANGADHAR\\anaconda3\\lib\\site-packages\\pip\\_vendor\\urllib3\\response.py\", line 541, in read\n",
      "    raise IncompleteRead(self._fp_bytes_read, self.length_remaining)\n",
      "  File \"C:\\Users\\SAI GANGADHAR\\anaconda3\\lib\\contextlib.py\", line 137, in __exit__\n",
      "    self.gen.throw(typ, value, traceback)\n",
      "  File \"C:\\Users\\SAI GANGADHAR\\anaconda3\\lib\\site-packages\\pip\\_vendor\\urllib3\\response.py\", line 443, in _error_catcher\n",
      "    raise ReadTimeoutError(self._pool, None, \"Read timed out.\")\n",
      "pip._vendor.urllib3.exceptions.ReadTimeoutError: HTTPSConnectionPool(host='files.pythonhosted.org', port=443): Read timed out.\n"
     ]
    }
   ],
   "source": [
    "pip install pgmpy"
   ]
  },
  {
   "cell_type": "code",
   "execution_count": 2,
   "id": "de4046df",
   "metadata": {},
   "outputs": [
    {
     "ename": "ModuleNotFoundError",
     "evalue": "No module named 'pgmpy'",
     "output_type": "error",
     "traceback": [
      "\u001b[1;31m---------------------------------------------------------------------------\u001b[0m",
      "\u001b[1;31mModuleNotFoundError\u001b[0m                       Traceback (most recent call last)",
      "\u001b[1;32mC:\\Users\\SAIGAN~1\\AppData\\Local\\Temp/ipykernel_19328/3924363235.py\u001b[0m in \u001b[0;36m<module>\u001b[1;34m\u001b[0m\n\u001b[1;32m----> 1\u001b[1;33m \u001b[1;32mimport\u001b[0m \u001b[0mpgmpy\u001b[0m\u001b[1;33m.\u001b[0m\u001b[0mmodels\u001b[0m\u001b[1;33m\u001b[0m\u001b[1;33m\u001b[0m\u001b[0m\n\u001b[0m",
      "\u001b[1;31mModuleNotFoundError\u001b[0m: No module named 'pgmpy'"
     ]
    }
   ],
   "source": [
    "import pgmpy.models"
   ]
  },
  {
   "cell_type": "code",
   "execution_count": null,
   "id": "a4e8cc01",
   "metadata": {},
   "outputs": [],
   "source": [
    "model = pgmpy.models.BayesianModel([('Burglary', 'Alarm'), \n",
    "                                    ('Earthquake', 'Alarm'),\n",
    "                                    ('Alarm', 'JohnCalls'), \n",
    "                                    ('Alarm', 'MaryCalls')])"
   ]
  },
  {
   "cell_type": "code",
   "execution_count": null,
   "id": "dd740b8d",
   "metadata": {},
   "outputs": [],
   "source": [
    "cpd_burglary = pgmpy.factors.discrete.TabularCPD('Burglary', 2, [[ 0.999],[0.001]])"
   ]
  },
  {
   "cell_type": "code",
   "execution_count": null,
   "id": "1be41423",
   "metadata": {},
   "outputs": [],
   "source": [
    "cpd_earthquake = pgmpy.factors.discrete.TabularCPD('Earthquake', 2, [[0.998],[0.002]])"
   ]
  },
  {
   "cell_type": "code",
   "execution_count": null,
   "id": "c9413fa8",
   "metadata": {},
   "outputs": [],
   "source": [
    "cpd_alarm = pgmpy.factors.discrete.TabularCPD('Alarm', 2, [[0.05, 0.06, 0.71, 0.999],[0.95, 0.94, 0.29, 0.001] ], \n",
    "                                              evidence=['Burglary', 'Earthquake'], \n",
    "                                              evidence_card=[2, 2])"
   ]
  },
  {
   "cell_type": "code",
   "execution_count": null,
   "id": "eb606f7a",
   "metadata": {},
   "outputs": [],
   "source": [
    "cpd_john = pgmpy.factors.discrete.TabularCPD('JohnCalls', 2, [[0.05,0.90], \n",
    "                                                           [0.95,0.10]], \n",
    "                                              evidence=['Alarm'], \n",
    "                                              evidence_card=[2])"
   ]
  },
  {
   "cell_type": "code",
   "execution_count": null,
   "id": "10006736",
   "metadata": {},
   "outputs": [],
   "source": [
    "cpd_mary = pgmpy.factors.discrete.TabularCPD('MaryCalls', 2, [[0.01,0.70], \n",
    "                                                           [0.99,0.30]], \n",
    "                                              evidence=['Alarm'], \n",
    "                                              evidence_card=[2])"
   ]
  },
  {
   "cell_type": "code",
   "execution_count": null,
   "id": "75fcaa9f",
   "metadata": {},
   "outputs": [],
   "source": [
    "model.add_cpds(cpd_burglary, cpd_earthquake, cpd_alarm, cpd_john, cpd_mary)"
   ]
  },
  {
   "cell_type": "code",
   "execution_count": null,
   "id": "34429d96",
   "metadata": {},
   "outputs": [],
   "source": [
    "model.check_model()"
   ]
  },
  {
   "cell_type": "code",
   "execution_count": 5,
   "id": "3b3d3162",
   "metadata": {},
   "outputs": [
    {
     "name": "stdout",
     "output_type": "stream",
     "text": [
      "Probability distribution, P(Burglary)\n"
     ]
    },
    {
     "ename": "NameError",
     "evalue": "name 'burglary' is not defined",
     "output_type": "error",
     "traceback": [
      "\u001b[1;31m---------------------------------------------------------------------------\u001b[0m",
      "\u001b[1;31mNameError\u001b[0m                                 Traceback (most recent call last)",
      "\u001b[1;32mC:\\Users\\SAIGAN~1\\AppData\\Local\\Temp/ipykernel_19328/3681787586.py\u001b[0m in \u001b[0;36m<module>\u001b[1;34m\u001b[0m\n\u001b[0;32m      1\u001b[0m \u001b[0mprint\u001b[0m\u001b[1;33m(\u001b[0m\u001b[1;34m'Probability distribution, P(Burglary)'\u001b[0m\u001b[1;33m)\u001b[0m\u001b[1;33m\u001b[0m\u001b[1;33m\u001b[0m\u001b[0m\n\u001b[1;32m----> 2\u001b[1;33m \u001b[0mprint\u001b[0m\u001b[1;33m(\u001b[0m\u001b[0mburglary\u001b[0m\u001b[1;33m)\u001b[0m\u001b[1;33m\u001b[0m\u001b[1;33m\u001b[0m\u001b[0m\n\u001b[0m\u001b[0;32m      3\u001b[0m \u001b[0mprint\u001b[0m\u001b[1;33m(\u001b[0m\u001b[1;33m)\u001b[0m\u001b[1;33m\u001b[0m\u001b[1;33m\u001b[0m\u001b[0m\n\u001b[0;32m      4\u001b[0m \u001b[0mprint\u001b[0m\u001b[1;33m(\u001b[0m\u001b[1;34m'Probability distribution, P(Earthquake)'\u001b[0m\u001b[1;33m)\u001b[0m\u001b[1;33m\u001b[0m\u001b[1;33m\u001b[0m\u001b[0m\n\u001b[0;32m      5\u001b[0m \u001b[0mprint\u001b[0m\u001b[1;33m(\u001b[0m\u001b[0mcpd_earthquake\u001b[0m\u001b[1;33m)\u001b[0m\u001b[1;33m\u001b[0m\u001b[1;33m\u001b[0m\u001b[0m\n",
      "\u001b[1;31mNameError\u001b[0m: name 'burglary' is not defined"
     ]
    }
   ],
   "source": [
    "print('Probability distribution, P(Burglary)')\n",
    "print(cpd_burglary)\n",
    "print()\n",
    "print('Probability distribution, P(Earthquake)')\n",
    "print(cpd_earthquake)\n",
    "print()\n",
    "print('Joint probability distribution, P(Alarm | Burglary, Earthquake)')\n",
    "print(cpd_alarm)\n",
    "print()\n",
    "print('Joint probability distribution, P(JohnCalls | Alarm)')\n",
    "print(cpd_john)\n",
    "print()\n",
    "print('Joint probability distribution, P(MaryCalls | Alarm)')\n",
    "print(cpd_mary)\n",
    "print()"
   ]
  },
  {
   "cell_type": "code",
   "execution_count": null,
   "id": "e2f02be8",
   "metadata": {},
   "outputs": [],
   "source": []
  }
 ],
 "metadata": {
  "kernelspec": {
   "display_name": "Python 3 (ipykernel)",
   "language": "python",
   "name": "python3"
  },
  "language_info": {
   "codemirror_mode": {
    "name": "ipython",
    "version": 3
   },
   "file_extension": ".py",
   "mimetype": "text/x-python",
   "name": "python",
   "nbconvert_exporter": "python",
   "pygments_lexer": "ipython3",
   "version": "3.9.7"
  }
 },
 "nbformat": 4,
 "nbformat_minor": 5
}
